{
 "cells": [
  {
   "cell_type": "code",
   "execution_count": 1,
   "metadata": {},
   "outputs": [],
   "source": [
    "\n",
    "import sys\n",
    "sys.path.append('../..')\n",
    "\n",
    "import os\n",
    "os.environ['PYTHONPATH'] = '../..'"
   ]
  },
  {
   "cell_type": "code",
   "execution_count": 2,
   "metadata": {},
   "outputs": [],
   "source": [
    "import Medfl\n"
   ]
  },
  {
   "cell_type": "code",
   "execution_count": 3,
   "metadata": {},
   "outputs": [
    {
     "name": "stderr",
     "output_type": "stream",
     "text": [
      "c:\\Python39\\lib\\site-packages\\tqdm\\auto.py:21: TqdmWarning: IProgress not found. Please update jupyter and ipywidgets. See https://ipywidgets.readthedocs.io/en/stable/user_install.html\n",
      "  from .autonotebook import tqdm as notebook_tqdm\n"
     ]
    },
    {
     "ename": "ProgrammingError",
     "evalue": "(mysql.connector.errors.ProgrammingError) 1045 (28000): Accès refusé pour l'utilisateur: 'ouael'@'@localhost' (mot de passe: OUI)\n(Background on this error at: https://sqlalche.me/e/14/f405)",
     "output_type": "error",
     "traceback": [
      "\u001b[1;31m---------------------------------------------------------------------------\u001b[0m",
      "\u001b[1;31mMySQLInterfaceError\u001b[0m                       Traceback (most recent call last)",
      "File \u001b[1;32mc:\\Python39\\lib\\site-packages\\mysql\\connector\\connection_cext.py:323\u001b[0m, in \u001b[0;36mCMySQLConnection._open_connection\u001b[1;34m(self)\u001b[0m\n\u001b[0;32m    322\u001b[0m \u001b[39mtry\u001b[39;00m:\n\u001b[1;32m--> 323\u001b[0m     \u001b[39mself\u001b[39m\u001b[39m.\u001b[39m_cmysql\u001b[39m.\u001b[39mconnect(\u001b[39m*\u001b[39m\u001b[39m*\u001b[39mcnx_kwargs)\n\u001b[0;32m    324\u001b[0m     \u001b[39mself\u001b[39m\u001b[39m.\u001b[39m_cmysql\u001b[39m.\u001b[39mconverter_str_fallback \u001b[39m=\u001b[39m \u001b[39mself\u001b[39m\u001b[39m.\u001b[39m_converter_str_fallback\n",
      "\u001b[1;31mMySQLInterfaceError\u001b[0m: Accès refusé pour l'utilisateur: 'ouael'@'@localhost' (mot de passe: OUI)",
      "\nThe above exception was the direct cause of the following exception:\n",
      "\u001b[1;31mProgrammingError\u001b[0m                          Traceback (most recent call last)",
      "File \u001b[1;32mc:\\Python39\\lib\\site-packages\\sqlalchemy\\engine\\base.py:3371\u001b[0m, in \u001b[0;36mEngine._wrap_pool_connect\u001b[1;34m(self, fn, connection)\u001b[0m\n\u001b[0;32m   3370\u001b[0m \u001b[39mtry\u001b[39;00m:\n\u001b[1;32m-> 3371\u001b[0m     \u001b[39mreturn\u001b[39;00m fn()\n\u001b[0;32m   3372\u001b[0m \u001b[39mexcept\u001b[39;00m dialect\u001b[39m.\u001b[39mdbapi\u001b[39m.\u001b[39mError \u001b[39mas\u001b[39;00m e:\n",
      "File \u001b[1;32mc:\\Python39\\lib\\site-packages\\sqlalchemy\\pool\\base.py:327\u001b[0m, in \u001b[0;36mPool.connect\u001b[1;34m(self)\u001b[0m\n\u001b[0;32m    320\u001b[0m \u001b[39m\u001b[39m\u001b[39m\"\"\"Return a DBAPI connection from the pool.\u001b[39;00m\n\u001b[0;32m    321\u001b[0m \n\u001b[0;32m    322\u001b[0m \u001b[39mThe connection is instrumented such that when its\u001b[39;00m\n\u001b[1;32m   (...)\u001b[0m\n\u001b[0;32m    325\u001b[0m \n\u001b[0;32m    326\u001b[0m \u001b[39m\"\"\"\u001b[39;00m\n\u001b[1;32m--> 327\u001b[0m \u001b[39mreturn\u001b[39;00m _ConnectionFairy\u001b[39m.\u001b[39;49m_checkout(\u001b[39mself\u001b[39;49m)\n",
      "File \u001b[1;32mc:\\Python39\\lib\\site-packages\\sqlalchemy\\pool\\base.py:894\u001b[0m, in \u001b[0;36m_ConnectionFairy._checkout\u001b[1;34m(cls, pool, threadconns, fairy)\u001b[0m\n\u001b[0;32m    893\u001b[0m \u001b[39mif\u001b[39;00m \u001b[39mnot\u001b[39;00m fairy:\n\u001b[1;32m--> 894\u001b[0m     fairy \u001b[39m=\u001b[39m _ConnectionRecord\u001b[39m.\u001b[39;49mcheckout(pool)\n\u001b[0;32m    896\u001b[0m     fairy\u001b[39m.\u001b[39m_pool \u001b[39m=\u001b[39m pool\n",
      "File \u001b[1;32mc:\\Python39\\lib\\site-packages\\sqlalchemy\\pool\\base.py:493\u001b[0m, in \u001b[0;36m_ConnectionRecord.checkout\u001b[1;34m(cls, pool)\u001b[0m\n\u001b[0;32m    491\u001b[0m \u001b[39m@classmethod\u001b[39m\n\u001b[0;32m    492\u001b[0m \u001b[39mdef\u001b[39;00m \u001b[39mcheckout\u001b[39m(\u001b[39mcls\u001b[39m, pool):\n\u001b[1;32m--> 493\u001b[0m     rec \u001b[39m=\u001b[39m pool\u001b[39m.\u001b[39;49m_do_get()\n\u001b[0;32m    494\u001b[0m     \u001b[39mtry\u001b[39;00m:\n",
      "File \u001b[1;32mc:\\Python39\\lib\\site-packages\\sqlalchemy\\pool\\impl.py:146\u001b[0m, in \u001b[0;36mQueuePool._do_get\u001b[1;34m(self)\u001b[0m\n\u001b[0;32m    145\u001b[0m         \u001b[39mwith\u001b[39;00m util\u001b[39m.\u001b[39msafe_reraise():\n\u001b[1;32m--> 146\u001b[0m             \u001b[39mself\u001b[39m\u001b[39m.\u001b[39m_dec_overflow()\n\u001b[0;32m    147\u001b[0m \u001b[39melse\u001b[39;00m:\n",
      "File \u001b[1;32mc:\\Python39\\lib\\site-packages\\sqlalchemy\\util\\langhelpers.py:70\u001b[0m, in \u001b[0;36msafe_reraise.__exit__\u001b[1;34m(self, type_, value, traceback)\u001b[0m\n\u001b[0;32m     69\u001b[0m     \u001b[39mif\u001b[39;00m \u001b[39mnot\u001b[39;00m \u001b[39mself\u001b[39m\u001b[39m.\u001b[39mwarn_only:\n\u001b[1;32m---> 70\u001b[0m         compat\u001b[39m.\u001b[39;49mraise_(\n\u001b[0;32m     71\u001b[0m             exc_value,\n\u001b[0;32m     72\u001b[0m             with_traceback\u001b[39m=\u001b[39;49mexc_tb,\n\u001b[0;32m     73\u001b[0m         )\n\u001b[0;32m     74\u001b[0m \u001b[39melse\u001b[39;00m:\n",
      "File \u001b[1;32mc:\\Python39\\lib\\site-packages\\sqlalchemy\\util\\compat.py:211\u001b[0m, in \u001b[0;36mraise_\u001b[1;34m(***failed resolving arguments***)\u001b[0m\n\u001b[0;32m    210\u001b[0m \u001b[39mtry\u001b[39;00m:\n\u001b[1;32m--> 211\u001b[0m     \u001b[39mraise\u001b[39;00m exception\n\u001b[0;32m    212\u001b[0m \u001b[39mfinally\u001b[39;00m:\n\u001b[0;32m    213\u001b[0m     \u001b[39m# credit to\u001b[39;00m\n\u001b[0;32m    214\u001b[0m     \u001b[39m# https://cosmicpercolator.com/2016/01/13/exception-leaks-in-python-2-and-3/\u001b[39;00m\n\u001b[0;32m    215\u001b[0m     \u001b[39m# as the __traceback__ object creates a cycle\u001b[39;00m\n",
      "File \u001b[1;32mc:\\Python39\\lib\\site-packages\\sqlalchemy\\pool\\impl.py:143\u001b[0m, in \u001b[0;36mQueuePool._do_get\u001b[1;34m(self)\u001b[0m\n\u001b[0;32m    142\u001b[0m \u001b[39mtry\u001b[39;00m:\n\u001b[1;32m--> 143\u001b[0m     \u001b[39mreturn\u001b[39;00m \u001b[39mself\u001b[39;49m\u001b[39m.\u001b[39;49m_create_connection()\n\u001b[0;32m    144\u001b[0m \u001b[39mexcept\u001b[39;00m:\n",
      "File \u001b[1;32mc:\\Python39\\lib\\site-packages\\sqlalchemy\\pool\\base.py:273\u001b[0m, in \u001b[0;36mPool._create_connection\u001b[1;34m(self)\u001b[0m\n\u001b[0;32m    271\u001b[0m \u001b[39m\u001b[39m\u001b[39m\"\"\"Called by subclasses to create a new ConnectionRecord.\"\"\"\u001b[39;00m\n\u001b[1;32m--> 273\u001b[0m \u001b[39mreturn\u001b[39;00m _ConnectionRecord(\u001b[39mself\u001b[39;49m)\n",
      "File \u001b[1;32mc:\\Python39\\lib\\site-packages\\sqlalchemy\\pool\\base.py:388\u001b[0m, in \u001b[0;36m_ConnectionRecord.__init__\u001b[1;34m(self, pool, connect)\u001b[0m\n\u001b[0;32m    387\u001b[0m \u001b[39mif\u001b[39;00m connect:\n\u001b[1;32m--> 388\u001b[0m     \u001b[39mself\u001b[39;49m\u001b[39m.\u001b[39;49m__connect()\n\u001b[0;32m    389\u001b[0m \u001b[39mself\u001b[39m\u001b[39m.\u001b[39mfinalize_callback \u001b[39m=\u001b[39m deque()\n",
      "File \u001b[1;32mc:\\Python39\\lib\\site-packages\\sqlalchemy\\pool\\base.py:691\u001b[0m, in \u001b[0;36m_ConnectionRecord.__connect\u001b[1;34m(self)\u001b[0m\n\u001b[0;32m    690\u001b[0m     \u001b[39mwith\u001b[39;00m util\u001b[39m.\u001b[39msafe_reraise():\n\u001b[1;32m--> 691\u001b[0m         pool\u001b[39m.\u001b[39mlogger\u001b[39m.\u001b[39mdebug(\u001b[39m\"\u001b[39m\u001b[39mError on connect(): \u001b[39m\u001b[39m%s\u001b[39;00m\u001b[39m\"\u001b[39m, e)\n\u001b[0;32m    692\u001b[0m \u001b[39melse\u001b[39;00m:\n\u001b[0;32m    693\u001b[0m     \u001b[39m# in SQLAlchemy 1.4 the first_connect event is not used by\u001b[39;00m\n\u001b[0;32m    694\u001b[0m     \u001b[39m# the engine, so this will usually not be set\u001b[39;00m\n",
      "File \u001b[1;32mc:\\Python39\\lib\\site-packages\\sqlalchemy\\util\\langhelpers.py:70\u001b[0m, in \u001b[0;36msafe_reraise.__exit__\u001b[1;34m(self, type_, value, traceback)\u001b[0m\n\u001b[0;32m     69\u001b[0m     \u001b[39mif\u001b[39;00m \u001b[39mnot\u001b[39;00m \u001b[39mself\u001b[39m\u001b[39m.\u001b[39mwarn_only:\n\u001b[1;32m---> 70\u001b[0m         compat\u001b[39m.\u001b[39;49mraise_(\n\u001b[0;32m     71\u001b[0m             exc_value,\n\u001b[0;32m     72\u001b[0m             with_traceback\u001b[39m=\u001b[39;49mexc_tb,\n\u001b[0;32m     73\u001b[0m         )\n\u001b[0;32m     74\u001b[0m \u001b[39melse\u001b[39;00m:\n",
      "File \u001b[1;32mc:\\Python39\\lib\\site-packages\\sqlalchemy\\util\\compat.py:211\u001b[0m, in \u001b[0;36mraise_\u001b[1;34m(***failed resolving arguments***)\u001b[0m\n\u001b[0;32m    210\u001b[0m \u001b[39mtry\u001b[39;00m:\n\u001b[1;32m--> 211\u001b[0m     \u001b[39mraise\u001b[39;00m exception\n\u001b[0;32m    212\u001b[0m \u001b[39mfinally\u001b[39;00m:\n\u001b[0;32m    213\u001b[0m     \u001b[39m# credit to\u001b[39;00m\n\u001b[0;32m    214\u001b[0m     \u001b[39m# https://cosmicpercolator.com/2016/01/13/exception-leaks-in-python-2-and-3/\u001b[39;00m\n\u001b[0;32m    215\u001b[0m     \u001b[39m# as the __traceback__ object creates a cycle\u001b[39;00m\n",
      "File \u001b[1;32mc:\\Python39\\lib\\site-packages\\sqlalchemy\\pool\\base.py:686\u001b[0m, in \u001b[0;36m_ConnectionRecord.__connect\u001b[1;34m(self)\u001b[0m\n\u001b[0;32m    685\u001b[0m \u001b[39mself\u001b[39m\u001b[39m.\u001b[39mstarttime \u001b[39m=\u001b[39m time\u001b[39m.\u001b[39mtime()\n\u001b[1;32m--> 686\u001b[0m \u001b[39mself\u001b[39m\u001b[39m.\u001b[39mdbapi_connection \u001b[39m=\u001b[39m connection \u001b[39m=\u001b[39m pool\u001b[39m.\u001b[39;49m_invoke_creator(\u001b[39mself\u001b[39;49m)\n\u001b[0;32m    687\u001b[0m pool\u001b[39m.\u001b[39mlogger\u001b[39m.\u001b[39mdebug(\u001b[39m\"\u001b[39m\u001b[39mCreated new connection \u001b[39m\u001b[39m%r\u001b[39;00m\u001b[39m\"\u001b[39m, connection)\n",
      "File \u001b[1;32mc:\\Python39\\lib\\site-packages\\sqlalchemy\\engine\\create.py:574\u001b[0m, in \u001b[0;36mcreate_engine.<locals>.connect\u001b[1;34m(connection_record)\u001b[0m\n\u001b[0;32m    573\u001b[0m             \u001b[39mreturn\u001b[39;00m connection\n\u001b[1;32m--> 574\u001b[0m \u001b[39mreturn\u001b[39;00m dialect\u001b[39m.\u001b[39mconnect(\u001b[39m*\u001b[39mcargs, \u001b[39m*\u001b[39m\u001b[39m*\u001b[39mcparams)\n",
      "File \u001b[1;32mc:\\Python39\\lib\\site-packages\\sqlalchemy\\engine\\default.py:598\u001b[0m, in \u001b[0;36mDefaultDialect.connect\u001b[1;34m(self, *cargs, **cparams)\u001b[0m\n\u001b[0;32m    596\u001b[0m \u001b[39mdef\u001b[39;00m \u001b[39mconnect\u001b[39m(\u001b[39mself\u001b[39m, \u001b[39m*\u001b[39mcargs, \u001b[39m*\u001b[39m\u001b[39m*\u001b[39mcparams):\n\u001b[0;32m    597\u001b[0m     \u001b[39m# inherits the docstring from interfaces.Dialect.connect\u001b[39;00m\n\u001b[1;32m--> 598\u001b[0m     \u001b[39mreturn\u001b[39;00m \u001b[39mself\u001b[39m\u001b[39m.\u001b[39mdbapi\u001b[39m.\u001b[39mconnect(\u001b[39m*\u001b[39mcargs, \u001b[39m*\u001b[39m\u001b[39m*\u001b[39mcparams)\n",
      "File \u001b[1;32mc:\\Python39\\lib\\site-packages\\mysql\\connector\\pooling.py:322\u001b[0m, in \u001b[0;36mconnect\u001b[1;34m(*args, **kwargs)\u001b[0m\n\u001b[0;32m    321\u001b[0m \u001b[39mif\u001b[39;00m CMySQLConnection \u001b[39mand\u001b[39;00m \u001b[39mnot\u001b[39;00m use_pure:\n\u001b[1;32m--> 322\u001b[0m     \u001b[39mreturn\u001b[39;00m CMySQLConnection(\u001b[39m*\u001b[39margs, \u001b[39m*\u001b[39m\u001b[39m*\u001b[39mkwargs)\n\u001b[0;32m    323\u001b[0m \u001b[39mreturn\u001b[39;00m MySQLConnection(\u001b[39m*\u001b[39margs, \u001b[39m*\u001b[39m\u001b[39m*\u001b[39mkwargs)\n",
      "File \u001b[1;32mc:\\Python39\\lib\\site-packages\\mysql\\connector\\connection_cext.py:140\u001b[0m, in \u001b[0;36mCMySQLConnection.__init__\u001b[1;34m(self, **kwargs)\u001b[0m\n\u001b[0;32m    139\u001b[0m \u001b[39mtry\u001b[39;00m:\n\u001b[1;32m--> 140\u001b[0m     \u001b[39mself\u001b[39m\u001b[39m.\u001b[39mconnect(\u001b[39m*\u001b[39m\u001b[39m*\u001b[39mkwargs)\n\u001b[0;32m    141\u001b[0m \u001b[39mexcept\u001b[39;00m \u001b[39mException\u001b[39;00m:\n",
      "File \u001b[1;32mc:\\Python39\\lib\\site-packages\\mysql\\connector\\abstracts.py:1363\u001b[0m, in \u001b[0;36mMySQLConnectionAbstract.connect\u001b[1;34m(self, **kwargs)\u001b[0m\n\u001b[0;32m   1362\u001b[0m \u001b[39mself\u001b[39m\u001b[39m.\u001b[39mdisconnect()\n\u001b[1;32m-> 1363\u001b[0m \u001b[39mself\u001b[39;49m\u001b[39m.\u001b[39;49m_open_connection()\n\u001b[0;32m   1365\u001b[0m charset, collation \u001b[39m=\u001b[39m (\n\u001b[0;32m   1366\u001b[0m     kwargs\u001b[39m.\u001b[39mpop(\u001b[39m\"\u001b[39m\u001b[39mcharset\u001b[39m\u001b[39m\"\u001b[39m, \u001b[39mNone\u001b[39;00m),\n\u001b[0;32m   1367\u001b[0m     kwargs\u001b[39m.\u001b[39mpop(\u001b[39m\"\u001b[39m\u001b[39mcollation\u001b[39m\u001b[39m\"\u001b[39m, \u001b[39mNone\u001b[39;00m),\n\u001b[0;32m   1368\u001b[0m )\n",
      "File \u001b[1;32mc:\\Python39\\lib\\site-packages\\mysql\\connector\\connection_cext.py:328\u001b[0m, in \u001b[0;36mCMySQLConnection._open_connection\u001b[1;34m(self)\u001b[0m\n\u001b[0;32m    327\u001b[0m \u001b[39mexcept\u001b[39;00m MySQLInterfaceError \u001b[39mas\u001b[39;00m err:\n\u001b[1;32m--> 328\u001b[0m     \u001b[39mraise\u001b[39;00m get_mysql_exception(\n\u001b[0;32m    329\u001b[0m         msg\u001b[39m=\u001b[39merr\u001b[39m.\u001b[39mmsg, errno\u001b[39m=\u001b[39merr\u001b[39m.\u001b[39merrno, sqlstate\u001b[39m=\u001b[39merr\u001b[39m.\u001b[39msqlstate\n\u001b[0;32m    330\u001b[0m     ) \u001b[39mfrom\u001b[39;00m \u001b[39merr\u001b[39;00m\n\u001b[0;32m    332\u001b[0m \u001b[39mself\u001b[39m\u001b[39m.\u001b[39m_do_handshake()\n",
      "\u001b[1;31mProgrammingError\u001b[0m: 1045 (28000): Accès refusé pour l'utilisateur: 'ouael'@'@localhost' (mot de passe: OUI)",
      "\nThe above exception was the direct cause of the following exception:\n",
      "\u001b[1;31mProgrammingError\u001b[0m                          Traceback (most recent call last)",
      "Cell \u001b[1;32mIn[3], line 1\u001b[0m\n\u001b[1;32m----> 1\u001b[0m \u001b[39mfrom\u001b[39;00m \u001b[39mMedfl\u001b[39;00m\u001b[39m.\u001b[39;00m\u001b[39mLearningManager\u001b[39;00m\u001b[39m.\u001b[39;00m\u001b[39mutils\u001b[39;00m \u001b[39mimport\u001b[39;00m \u001b[39m*\u001b[39m\n",
      "File \u001b[1;32m~\\AppData\\Roaming\\Python\\Python39\\site-packages\\Medfl\\LearningManager\\utils.py:9\u001b[0m\n\u001b[0;32m      6\u001b[0m \u001b[39mfrom\u001b[39;00m \u001b[39msklearn\u001b[39;00m\u001b[39m.\u001b[39;00m\u001b[39mmetrics\u001b[39;00m \u001b[39mimport\u001b[39;00m \u001b[39m*\u001b[39m\n\u001b[0;32m      7\u001b[0m \u001b[39mfrom\u001b[39;00m \u001b[39myaml\u001b[39;00m\u001b[39m.\u001b[39;00m\u001b[39mloader\u001b[39;00m \u001b[39mimport\u001b[39;00m SafeLoader\n\u001b[1;32m----> 9\u001b[0m \u001b[39mfrom\u001b[39;00m \u001b[39mscripts\u001b[39;00m\u001b[39m.\u001b[39;00m\u001b[39mbase\u001b[39;00m \u001b[39mimport\u001b[39;00m \u001b[39m*\u001b[39m\n\u001b[0;32m     10\u001b[0m \u001b[39mimport\u001b[39;00m \u001b[39mjson\u001b[39;00m\n\u001b[0;32m     13\u001b[0m \u001b[39mimport\u001b[39;00m \u001b[39mpandas\u001b[39;00m \u001b[39mas\u001b[39;00m \u001b[39mpd\u001b[39;00m\n",
      "File \u001b[1;32m~\\AppData\\Roaming\\Python\\Python39\\site-packages\\scripts\\base.py:30\u001b[0m\n\u001b[0;32m     20\u001b[0m connection_string \u001b[39m=\u001b[39m (\n\u001b[0;32m     21\u001b[0m     \u001b[39mf\u001b[39m\u001b[39m\"\u001b[39m\u001b[39mmysql+mysqlconnector://\u001b[39m\u001b[39m{\u001b[39;00mmysql_config[\u001b[39m'\u001b[39m\u001b[39muser\u001b[39m\u001b[39m'\u001b[39m]\u001b[39m}\u001b[39;00m\u001b[39m:\u001b[39m\u001b[39m{\u001b[39;00mmysql_config[\u001b[39m'\u001b[39m\u001b[39mpassword\u001b[39m\u001b[39m'\u001b[39m]\u001b[39m}\u001b[39;00m\u001b[39m@\u001b[39m\u001b[39m\"\u001b[39m\n\u001b[0;32m     22\u001b[0m     \u001b[39mf\u001b[39m\u001b[39m\"\u001b[39m\u001b[39m{\u001b[39;00mmysql_config[\u001b[39m'\u001b[39m\u001b[39mhost\u001b[39m\u001b[39m'\u001b[39m]\u001b[39m}\u001b[39;00m\u001b[39m:\u001b[39m\u001b[39m{\u001b[39;00mmysql_config[\u001b[39m'\u001b[39m\u001b[39mport\u001b[39m\u001b[39m'\u001b[39m]\u001b[39m}\u001b[39;00m\u001b[39m/\u001b[39m\u001b[39m{\u001b[39;00mmysql_config[\u001b[39m'\u001b[39m\u001b[39mdatabase\u001b[39m\u001b[39m'\u001b[39m]\u001b[39m}\u001b[39;00m\u001b[39m\"\u001b[39m\n\u001b[0;32m     23\u001b[0m )\n\u001b[0;32m     25\u001b[0m eng \u001b[39m=\u001b[39m create_engine(\n\u001b[0;32m     26\u001b[0m     connection_string,\n\u001b[0;32m     27\u001b[0m     execution_options\u001b[39m=\u001b[39m{\u001b[39m\"\u001b[39m\u001b[39mautocommit\u001b[39m\u001b[39m\"\u001b[39m: \u001b[39mTrue\u001b[39;00m},\n\u001b[0;32m     28\u001b[0m )\n\u001b[1;32m---> 30\u001b[0m my_eng \u001b[39m=\u001b[39m eng\u001b[39m.\u001b[39;49mconnect()\n",
      "File \u001b[1;32mc:\\Python39\\lib\\site-packages\\sqlalchemy\\engine\\base.py:3325\u001b[0m, in \u001b[0;36mEngine.connect\u001b[1;34m(self, close_with_result)\u001b[0m\n\u001b[0;32m   3310\u001b[0m \u001b[39mdef\u001b[39;00m \u001b[39mconnect\u001b[39m(\u001b[39mself\u001b[39m, close_with_result\u001b[39m=\u001b[39m\u001b[39mFalse\u001b[39;00m):\n\u001b[0;32m   3311\u001b[0m \u001b[39m    \u001b[39m\u001b[39m\"\"\"Return a new :class:`_engine.Connection` object.\u001b[39;00m\n\u001b[0;32m   3312\u001b[0m \n\u001b[0;32m   3313\u001b[0m \u001b[39m    The :class:`_engine.Connection` object is a facade that uses a DBAPI\u001b[39;00m\n\u001b[1;32m   (...)\u001b[0m\n\u001b[0;32m   3322\u001b[0m \n\u001b[0;32m   3323\u001b[0m \u001b[39m    \"\"\"\u001b[39;00m\n\u001b[1;32m-> 3325\u001b[0m     \u001b[39mreturn\u001b[39;00m \u001b[39mself\u001b[39;49m\u001b[39m.\u001b[39;49m_connection_cls(\u001b[39mself\u001b[39;49m, close_with_result\u001b[39m=\u001b[39;49mclose_with_result)\n",
      "File \u001b[1;32mc:\\Python39\\lib\\site-packages\\sqlalchemy\\engine\\base.py:96\u001b[0m, in \u001b[0;36mConnection.__init__\u001b[1;34m(self, engine, connection, close_with_result, _branch_from, _execution_options, _dispatch, _has_events, _allow_revalidate)\u001b[0m\n\u001b[0;32m     91\u001b[0m     \u001b[39mself\u001b[39m\u001b[39m.\u001b[39m_has_events \u001b[39m=\u001b[39m _branch_from\u001b[39m.\u001b[39m_has_events\n\u001b[0;32m     92\u001b[0m \u001b[39melse\u001b[39;00m:\n\u001b[0;32m     93\u001b[0m     \u001b[39mself\u001b[39m\u001b[39m.\u001b[39m_dbapi_connection \u001b[39m=\u001b[39m (\n\u001b[0;32m     94\u001b[0m         connection\n\u001b[0;32m     95\u001b[0m         \u001b[39mif\u001b[39;00m connection \u001b[39mis\u001b[39;00m \u001b[39mnot\u001b[39;00m \u001b[39mNone\u001b[39;00m\n\u001b[1;32m---> 96\u001b[0m         \u001b[39melse\u001b[39;00m engine\u001b[39m.\u001b[39;49mraw_connection()\n\u001b[0;32m     97\u001b[0m     )\n\u001b[0;32m     99\u001b[0m     \u001b[39mself\u001b[39m\u001b[39m.\u001b[39m_transaction \u001b[39m=\u001b[39m \u001b[39mself\u001b[39m\u001b[39m.\u001b[39m_nested_transaction \u001b[39m=\u001b[39m \u001b[39mNone\u001b[39;00m\n\u001b[0;32m    100\u001b[0m     \u001b[39mself\u001b[39m\u001b[39m.\u001b[39m__savepoint_seq \u001b[39m=\u001b[39m \u001b[39m0\u001b[39m\n",
      "File \u001b[1;32mc:\\Python39\\lib\\site-packages\\sqlalchemy\\engine\\base.py:3404\u001b[0m, in \u001b[0;36mEngine.raw_connection\u001b[1;34m(self, _connection)\u001b[0m\n\u001b[0;32m   3382\u001b[0m \u001b[39mdef\u001b[39;00m \u001b[39mraw_connection\u001b[39m(\u001b[39mself\u001b[39m, _connection\u001b[39m=\u001b[39m\u001b[39mNone\u001b[39;00m):\n\u001b[0;32m   3383\u001b[0m \u001b[39m    \u001b[39m\u001b[39m\"\"\"Return a \"raw\" DBAPI connection from the connection pool.\u001b[39;00m\n\u001b[0;32m   3384\u001b[0m \n\u001b[0;32m   3385\u001b[0m \u001b[39m    The returned object is a proxied version of the DBAPI\u001b[39;00m\n\u001b[1;32m   (...)\u001b[0m\n\u001b[0;32m   3402\u001b[0m \n\u001b[0;32m   3403\u001b[0m \u001b[39m    \"\"\"\u001b[39;00m\n\u001b[1;32m-> 3404\u001b[0m     \u001b[39mreturn\u001b[39;00m \u001b[39mself\u001b[39;49m\u001b[39m.\u001b[39;49m_wrap_pool_connect(\u001b[39mself\u001b[39;49m\u001b[39m.\u001b[39;49mpool\u001b[39m.\u001b[39;49mconnect, _connection)\n",
      "File \u001b[1;32mc:\\Python39\\lib\\site-packages\\sqlalchemy\\engine\\base.py:3374\u001b[0m, in \u001b[0;36mEngine._wrap_pool_connect\u001b[1;34m(self, fn, connection)\u001b[0m\n\u001b[0;32m   3372\u001b[0m \u001b[39mexcept\u001b[39;00m dialect\u001b[39m.\u001b[39mdbapi\u001b[39m.\u001b[39mError \u001b[39mas\u001b[39;00m e:\n\u001b[0;32m   3373\u001b[0m     \u001b[39mif\u001b[39;00m connection \u001b[39mis\u001b[39;00m \u001b[39mNone\u001b[39;00m:\n\u001b[1;32m-> 3374\u001b[0m         Connection\u001b[39m.\u001b[39;49m_handle_dbapi_exception_noconnection(\n\u001b[0;32m   3375\u001b[0m             e, dialect, \u001b[39mself\u001b[39;49m\n\u001b[0;32m   3376\u001b[0m         )\n\u001b[0;32m   3377\u001b[0m     \u001b[39melse\u001b[39;00m:\n\u001b[0;32m   3378\u001b[0m         util\u001b[39m.\u001b[39mraise_(\n\u001b[0;32m   3379\u001b[0m             sys\u001b[39m.\u001b[39mexc_info()[\u001b[39m1\u001b[39m], with_traceback\u001b[39m=\u001b[39msys\u001b[39m.\u001b[39mexc_info()[\u001b[39m2\u001b[39m]\n\u001b[0;32m   3380\u001b[0m         )\n",
      "File \u001b[1;32mc:\\Python39\\lib\\site-packages\\sqlalchemy\\engine\\base.py:2208\u001b[0m, in \u001b[0;36mConnection._handle_dbapi_exception_noconnection\u001b[1;34m(cls, e, dialect, engine)\u001b[0m\n\u001b[0;32m   2206\u001b[0m     util\u001b[39m.\u001b[39mraise_(newraise, with_traceback\u001b[39m=\u001b[39mexc_info[\u001b[39m2\u001b[39m], from_\u001b[39m=\u001b[39me)\n\u001b[0;32m   2207\u001b[0m \u001b[39melif\u001b[39;00m should_wrap:\n\u001b[1;32m-> 2208\u001b[0m     util\u001b[39m.\u001b[39;49mraise_(\n\u001b[0;32m   2209\u001b[0m         sqlalchemy_exception, with_traceback\u001b[39m=\u001b[39;49mexc_info[\u001b[39m2\u001b[39;49m], from_\u001b[39m=\u001b[39;49me\n\u001b[0;32m   2210\u001b[0m     )\n\u001b[0;32m   2211\u001b[0m \u001b[39melse\u001b[39;00m:\n\u001b[0;32m   2212\u001b[0m     util\u001b[39m.\u001b[39mraise_(exc_info[\u001b[39m1\u001b[39m], with_traceback\u001b[39m=\u001b[39mexc_info[\u001b[39m2\u001b[39m])\n",
      "File \u001b[1;32mc:\\Python39\\lib\\site-packages\\sqlalchemy\\util\\compat.py:211\u001b[0m, in \u001b[0;36mraise_\u001b[1;34m(***failed resolving arguments***)\u001b[0m\n\u001b[0;32m    208\u001b[0m     exception\u001b[39m.\u001b[39m__cause__ \u001b[39m=\u001b[39m replace_context\n\u001b[0;32m    210\u001b[0m \u001b[39mtry\u001b[39;00m:\n\u001b[1;32m--> 211\u001b[0m     \u001b[39mraise\u001b[39;00m exception\n\u001b[0;32m    212\u001b[0m \u001b[39mfinally\u001b[39;00m:\n\u001b[0;32m    213\u001b[0m     \u001b[39m# credit to\u001b[39;00m\n\u001b[0;32m    214\u001b[0m     \u001b[39m# https://cosmicpercolator.com/2016/01/13/exception-leaks-in-python-2-and-3/\u001b[39;00m\n\u001b[0;32m    215\u001b[0m     \u001b[39m# as the __traceback__ object creates a cycle\u001b[39;00m\n\u001b[0;32m    216\u001b[0m     \u001b[39mdel\u001b[39;00m exception, replace_context, from_, with_traceback\n",
      "File \u001b[1;32mc:\\Python39\\lib\\site-packages\\sqlalchemy\\engine\\base.py:3371\u001b[0m, in \u001b[0;36mEngine._wrap_pool_connect\u001b[1;34m(self, fn, connection)\u001b[0m\n\u001b[0;32m   3369\u001b[0m dialect \u001b[39m=\u001b[39m \u001b[39mself\u001b[39m\u001b[39m.\u001b[39mdialect\n\u001b[0;32m   3370\u001b[0m \u001b[39mtry\u001b[39;00m:\n\u001b[1;32m-> 3371\u001b[0m     \u001b[39mreturn\u001b[39;00m fn()\n\u001b[0;32m   3372\u001b[0m \u001b[39mexcept\u001b[39;00m dialect\u001b[39m.\u001b[39mdbapi\u001b[39m.\u001b[39mError \u001b[39mas\u001b[39;00m e:\n\u001b[0;32m   3373\u001b[0m     \u001b[39mif\u001b[39;00m connection \u001b[39mis\u001b[39;00m \u001b[39mNone\u001b[39;00m:\n",
      "File \u001b[1;32mc:\\Python39\\lib\\site-packages\\sqlalchemy\\pool\\base.py:327\u001b[0m, in \u001b[0;36mPool.connect\u001b[1;34m(self)\u001b[0m\n\u001b[0;32m    319\u001b[0m \u001b[39mdef\u001b[39;00m \u001b[39mconnect\u001b[39m(\u001b[39mself\u001b[39m):\n\u001b[0;32m    320\u001b[0m \u001b[39m    \u001b[39m\u001b[39m\"\"\"Return a DBAPI connection from the pool.\u001b[39;00m\n\u001b[0;32m    321\u001b[0m \n\u001b[0;32m    322\u001b[0m \u001b[39m    The connection is instrumented such that when its\u001b[39;00m\n\u001b[1;32m   (...)\u001b[0m\n\u001b[0;32m    325\u001b[0m \n\u001b[0;32m    326\u001b[0m \u001b[39m    \"\"\"\u001b[39;00m\n\u001b[1;32m--> 327\u001b[0m     \u001b[39mreturn\u001b[39;00m _ConnectionFairy\u001b[39m.\u001b[39;49m_checkout(\u001b[39mself\u001b[39;49m)\n",
      "File \u001b[1;32mc:\\Python39\\lib\\site-packages\\sqlalchemy\\pool\\base.py:894\u001b[0m, in \u001b[0;36m_ConnectionFairy._checkout\u001b[1;34m(cls, pool, threadconns, fairy)\u001b[0m\n\u001b[0;32m    891\u001b[0m \u001b[39m@classmethod\u001b[39m\n\u001b[0;32m    892\u001b[0m \u001b[39mdef\u001b[39;00m \u001b[39m_checkout\u001b[39m(\u001b[39mcls\u001b[39m, pool, threadconns\u001b[39m=\u001b[39m\u001b[39mNone\u001b[39;00m, fairy\u001b[39m=\u001b[39m\u001b[39mNone\u001b[39;00m):\n\u001b[0;32m    893\u001b[0m     \u001b[39mif\u001b[39;00m \u001b[39mnot\u001b[39;00m fairy:\n\u001b[1;32m--> 894\u001b[0m         fairy \u001b[39m=\u001b[39m _ConnectionRecord\u001b[39m.\u001b[39;49mcheckout(pool)\n\u001b[0;32m    896\u001b[0m         fairy\u001b[39m.\u001b[39m_pool \u001b[39m=\u001b[39m pool\n\u001b[0;32m    897\u001b[0m         fairy\u001b[39m.\u001b[39m_counter \u001b[39m=\u001b[39m \u001b[39m0\u001b[39m\n",
      "File \u001b[1;32mc:\\Python39\\lib\\site-packages\\sqlalchemy\\pool\\base.py:493\u001b[0m, in \u001b[0;36m_ConnectionRecord.checkout\u001b[1;34m(cls, pool)\u001b[0m\n\u001b[0;32m    491\u001b[0m \u001b[39m@classmethod\u001b[39m\n\u001b[0;32m    492\u001b[0m \u001b[39mdef\u001b[39;00m \u001b[39mcheckout\u001b[39m(\u001b[39mcls\u001b[39m, pool):\n\u001b[1;32m--> 493\u001b[0m     rec \u001b[39m=\u001b[39m pool\u001b[39m.\u001b[39;49m_do_get()\n\u001b[0;32m    494\u001b[0m     \u001b[39mtry\u001b[39;00m:\n\u001b[0;32m    495\u001b[0m         dbapi_connection \u001b[39m=\u001b[39m rec\u001b[39m.\u001b[39mget_connection()\n",
      "File \u001b[1;32mc:\\Python39\\lib\\site-packages\\sqlalchemy\\pool\\impl.py:146\u001b[0m, in \u001b[0;36mQueuePool._do_get\u001b[1;34m(self)\u001b[0m\n\u001b[0;32m    144\u001b[0m     \u001b[39mexcept\u001b[39;00m:\n\u001b[0;32m    145\u001b[0m         \u001b[39mwith\u001b[39;00m util\u001b[39m.\u001b[39msafe_reraise():\n\u001b[1;32m--> 146\u001b[0m             \u001b[39mself\u001b[39m\u001b[39m.\u001b[39m_dec_overflow()\n\u001b[0;32m    147\u001b[0m \u001b[39melse\u001b[39;00m:\n\u001b[0;32m    148\u001b[0m     \u001b[39mreturn\u001b[39;00m \u001b[39mself\u001b[39m\u001b[39m.\u001b[39m_do_get()\n",
      "File \u001b[1;32mc:\\Python39\\lib\\site-packages\\sqlalchemy\\util\\langhelpers.py:70\u001b[0m, in \u001b[0;36msafe_reraise.__exit__\u001b[1;34m(self, type_, value, traceback)\u001b[0m\n\u001b[0;32m     68\u001b[0m     \u001b[39mself\u001b[39m\u001b[39m.\u001b[39m_exc_info \u001b[39m=\u001b[39m \u001b[39mNone\u001b[39;00m  \u001b[39m# remove potential circular references\u001b[39;00m\n\u001b[0;32m     69\u001b[0m     \u001b[39mif\u001b[39;00m \u001b[39mnot\u001b[39;00m \u001b[39mself\u001b[39m\u001b[39m.\u001b[39mwarn_only:\n\u001b[1;32m---> 70\u001b[0m         compat\u001b[39m.\u001b[39;49mraise_(\n\u001b[0;32m     71\u001b[0m             exc_value,\n\u001b[0;32m     72\u001b[0m             with_traceback\u001b[39m=\u001b[39;49mexc_tb,\n\u001b[0;32m     73\u001b[0m         )\n\u001b[0;32m     74\u001b[0m \u001b[39melse\u001b[39;00m:\n\u001b[0;32m     75\u001b[0m     \u001b[39mif\u001b[39;00m \u001b[39mnot\u001b[39;00m compat\u001b[39m.\u001b[39mpy3k \u001b[39mand\u001b[39;00m \u001b[39mself\u001b[39m\u001b[39m.\u001b[39m_exc_info \u001b[39mand\u001b[39;00m \u001b[39mself\u001b[39m\u001b[39m.\u001b[39m_exc_info[\u001b[39m1\u001b[39m]:\n\u001b[0;32m     76\u001b[0m         \u001b[39m# emulate Py3K's behavior of telling us when an exception\u001b[39;00m\n\u001b[0;32m     77\u001b[0m         \u001b[39m# occurs in an exception handler.\u001b[39;00m\n",
      "File \u001b[1;32mc:\\Python39\\lib\\site-packages\\sqlalchemy\\util\\compat.py:211\u001b[0m, in \u001b[0;36mraise_\u001b[1;34m(***failed resolving arguments***)\u001b[0m\n\u001b[0;32m    208\u001b[0m     exception\u001b[39m.\u001b[39m__cause__ \u001b[39m=\u001b[39m replace_context\n\u001b[0;32m    210\u001b[0m \u001b[39mtry\u001b[39;00m:\n\u001b[1;32m--> 211\u001b[0m     \u001b[39mraise\u001b[39;00m exception\n\u001b[0;32m    212\u001b[0m \u001b[39mfinally\u001b[39;00m:\n\u001b[0;32m    213\u001b[0m     \u001b[39m# credit to\u001b[39;00m\n\u001b[0;32m    214\u001b[0m     \u001b[39m# https://cosmicpercolator.com/2016/01/13/exception-leaks-in-python-2-and-3/\u001b[39;00m\n\u001b[0;32m    215\u001b[0m     \u001b[39m# as the __traceback__ object creates a cycle\u001b[39;00m\n\u001b[0;32m    216\u001b[0m     \u001b[39mdel\u001b[39;00m exception, replace_context, from_, with_traceback\n",
      "File \u001b[1;32mc:\\Python39\\lib\\site-packages\\sqlalchemy\\pool\\impl.py:143\u001b[0m, in \u001b[0;36mQueuePool._do_get\u001b[1;34m(self)\u001b[0m\n\u001b[0;32m    141\u001b[0m \u001b[39mif\u001b[39;00m \u001b[39mself\u001b[39m\u001b[39m.\u001b[39m_inc_overflow():\n\u001b[0;32m    142\u001b[0m     \u001b[39mtry\u001b[39;00m:\n\u001b[1;32m--> 143\u001b[0m         \u001b[39mreturn\u001b[39;00m \u001b[39mself\u001b[39;49m\u001b[39m.\u001b[39;49m_create_connection()\n\u001b[0;32m    144\u001b[0m     \u001b[39mexcept\u001b[39;00m:\n\u001b[0;32m    145\u001b[0m         \u001b[39mwith\u001b[39;00m util\u001b[39m.\u001b[39msafe_reraise():\n",
      "File \u001b[1;32mc:\\Python39\\lib\\site-packages\\sqlalchemy\\pool\\base.py:273\u001b[0m, in \u001b[0;36mPool._create_connection\u001b[1;34m(self)\u001b[0m\n\u001b[0;32m    270\u001b[0m \u001b[39mdef\u001b[39;00m \u001b[39m_create_connection\u001b[39m(\u001b[39mself\u001b[39m):\n\u001b[0;32m    271\u001b[0m \u001b[39m    \u001b[39m\u001b[39m\"\"\"Called by subclasses to create a new ConnectionRecord.\"\"\"\u001b[39;00m\n\u001b[1;32m--> 273\u001b[0m     \u001b[39mreturn\u001b[39;00m _ConnectionRecord(\u001b[39mself\u001b[39;49m)\n",
      "File \u001b[1;32mc:\\Python39\\lib\\site-packages\\sqlalchemy\\pool\\base.py:388\u001b[0m, in \u001b[0;36m_ConnectionRecord.__init__\u001b[1;34m(self, pool, connect)\u001b[0m\n\u001b[0;32m    386\u001b[0m \u001b[39mself\u001b[39m\u001b[39m.\u001b[39m__pool \u001b[39m=\u001b[39m pool\n\u001b[0;32m    387\u001b[0m \u001b[39mif\u001b[39;00m connect:\n\u001b[1;32m--> 388\u001b[0m     \u001b[39mself\u001b[39;49m\u001b[39m.\u001b[39;49m__connect()\n\u001b[0;32m    389\u001b[0m \u001b[39mself\u001b[39m\u001b[39m.\u001b[39mfinalize_callback \u001b[39m=\u001b[39m deque()\n",
      "File \u001b[1;32mc:\\Python39\\lib\\site-packages\\sqlalchemy\\pool\\base.py:691\u001b[0m, in \u001b[0;36m_ConnectionRecord.__connect\u001b[1;34m(self)\u001b[0m\n\u001b[0;32m    689\u001b[0m \u001b[39mexcept\u001b[39;00m \u001b[39mBaseException\u001b[39;00m \u001b[39mas\u001b[39;00m e:\n\u001b[0;32m    690\u001b[0m     \u001b[39mwith\u001b[39;00m util\u001b[39m.\u001b[39msafe_reraise():\n\u001b[1;32m--> 691\u001b[0m         pool\u001b[39m.\u001b[39mlogger\u001b[39m.\u001b[39mdebug(\u001b[39m\"\u001b[39m\u001b[39mError on connect(): \u001b[39m\u001b[39m%s\u001b[39;00m\u001b[39m\"\u001b[39m, e)\n\u001b[0;32m    692\u001b[0m \u001b[39melse\u001b[39;00m:\n\u001b[0;32m    693\u001b[0m     \u001b[39m# in SQLAlchemy 1.4 the first_connect event is not used by\u001b[39;00m\n\u001b[0;32m    694\u001b[0m     \u001b[39m# the engine, so this will usually not be set\u001b[39;00m\n\u001b[0;32m    695\u001b[0m     \u001b[39mif\u001b[39;00m pool\u001b[39m.\u001b[39mdispatch\u001b[39m.\u001b[39mfirst_connect:\n",
      "File \u001b[1;32mc:\\Python39\\lib\\site-packages\\sqlalchemy\\util\\langhelpers.py:70\u001b[0m, in \u001b[0;36msafe_reraise.__exit__\u001b[1;34m(self, type_, value, traceback)\u001b[0m\n\u001b[0;32m     68\u001b[0m     \u001b[39mself\u001b[39m\u001b[39m.\u001b[39m_exc_info \u001b[39m=\u001b[39m \u001b[39mNone\u001b[39;00m  \u001b[39m# remove potential circular references\u001b[39;00m\n\u001b[0;32m     69\u001b[0m     \u001b[39mif\u001b[39;00m \u001b[39mnot\u001b[39;00m \u001b[39mself\u001b[39m\u001b[39m.\u001b[39mwarn_only:\n\u001b[1;32m---> 70\u001b[0m         compat\u001b[39m.\u001b[39;49mraise_(\n\u001b[0;32m     71\u001b[0m             exc_value,\n\u001b[0;32m     72\u001b[0m             with_traceback\u001b[39m=\u001b[39;49mexc_tb,\n\u001b[0;32m     73\u001b[0m         )\n\u001b[0;32m     74\u001b[0m \u001b[39melse\u001b[39;00m:\n\u001b[0;32m     75\u001b[0m     \u001b[39mif\u001b[39;00m \u001b[39mnot\u001b[39;00m compat\u001b[39m.\u001b[39mpy3k \u001b[39mand\u001b[39;00m \u001b[39mself\u001b[39m\u001b[39m.\u001b[39m_exc_info \u001b[39mand\u001b[39;00m \u001b[39mself\u001b[39m\u001b[39m.\u001b[39m_exc_info[\u001b[39m1\u001b[39m]:\n\u001b[0;32m     76\u001b[0m         \u001b[39m# emulate Py3K's behavior of telling us when an exception\u001b[39;00m\n\u001b[0;32m     77\u001b[0m         \u001b[39m# occurs in an exception handler.\u001b[39;00m\n",
      "File \u001b[1;32mc:\\Python39\\lib\\site-packages\\sqlalchemy\\util\\compat.py:211\u001b[0m, in \u001b[0;36mraise_\u001b[1;34m(***failed resolving arguments***)\u001b[0m\n\u001b[0;32m    208\u001b[0m     exception\u001b[39m.\u001b[39m__cause__ \u001b[39m=\u001b[39m replace_context\n\u001b[0;32m    210\u001b[0m \u001b[39mtry\u001b[39;00m:\n\u001b[1;32m--> 211\u001b[0m     \u001b[39mraise\u001b[39;00m exception\n\u001b[0;32m    212\u001b[0m \u001b[39mfinally\u001b[39;00m:\n\u001b[0;32m    213\u001b[0m     \u001b[39m# credit to\u001b[39;00m\n\u001b[0;32m    214\u001b[0m     \u001b[39m# https://cosmicpercolator.com/2016/01/13/exception-leaks-in-python-2-and-3/\u001b[39;00m\n\u001b[0;32m    215\u001b[0m     \u001b[39m# as the __traceback__ object creates a cycle\u001b[39;00m\n\u001b[0;32m    216\u001b[0m     \u001b[39mdel\u001b[39;00m exception, replace_context, from_, with_traceback\n",
      "File \u001b[1;32mc:\\Python39\\lib\\site-packages\\sqlalchemy\\pool\\base.py:686\u001b[0m, in \u001b[0;36m_ConnectionRecord.__connect\u001b[1;34m(self)\u001b[0m\n\u001b[0;32m    684\u001b[0m \u001b[39mtry\u001b[39;00m:\n\u001b[0;32m    685\u001b[0m     \u001b[39mself\u001b[39m\u001b[39m.\u001b[39mstarttime \u001b[39m=\u001b[39m time\u001b[39m.\u001b[39mtime()\n\u001b[1;32m--> 686\u001b[0m     \u001b[39mself\u001b[39m\u001b[39m.\u001b[39mdbapi_connection \u001b[39m=\u001b[39m connection \u001b[39m=\u001b[39m pool\u001b[39m.\u001b[39;49m_invoke_creator(\u001b[39mself\u001b[39;49m)\n\u001b[0;32m    687\u001b[0m     pool\u001b[39m.\u001b[39mlogger\u001b[39m.\u001b[39mdebug(\u001b[39m\"\u001b[39m\u001b[39mCreated new connection \u001b[39m\u001b[39m%r\u001b[39;00m\u001b[39m\"\u001b[39m, connection)\n\u001b[0;32m    688\u001b[0m     \u001b[39mself\u001b[39m\u001b[39m.\u001b[39mfresh \u001b[39m=\u001b[39m \u001b[39mTrue\u001b[39;00m\n",
      "File \u001b[1;32mc:\\Python39\\lib\\site-packages\\sqlalchemy\\engine\\create.py:574\u001b[0m, in \u001b[0;36mcreate_engine.<locals>.connect\u001b[1;34m(connection_record)\u001b[0m\n\u001b[0;32m    572\u001b[0m         \u001b[39mif\u001b[39;00m connection \u001b[39mis\u001b[39;00m \u001b[39mnot\u001b[39;00m \u001b[39mNone\u001b[39;00m:\n\u001b[0;32m    573\u001b[0m             \u001b[39mreturn\u001b[39;00m connection\n\u001b[1;32m--> 574\u001b[0m \u001b[39mreturn\u001b[39;00m dialect\u001b[39m.\u001b[39mconnect(\u001b[39m*\u001b[39mcargs, \u001b[39m*\u001b[39m\u001b[39m*\u001b[39mcparams)\n",
      "File \u001b[1;32mc:\\Python39\\lib\\site-packages\\sqlalchemy\\engine\\default.py:598\u001b[0m, in \u001b[0;36mDefaultDialect.connect\u001b[1;34m(self, *cargs, **cparams)\u001b[0m\n\u001b[0;32m    596\u001b[0m \u001b[39mdef\u001b[39;00m \u001b[39mconnect\u001b[39m(\u001b[39mself\u001b[39m, \u001b[39m*\u001b[39mcargs, \u001b[39m*\u001b[39m\u001b[39m*\u001b[39mcparams):\n\u001b[0;32m    597\u001b[0m     \u001b[39m# inherits the docstring from interfaces.Dialect.connect\u001b[39;00m\n\u001b[1;32m--> 598\u001b[0m     \u001b[39mreturn\u001b[39;00m \u001b[39mself\u001b[39m\u001b[39m.\u001b[39mdbapi\u001b[39m.\u001b[39mconnect(\u001b[39m*\u001b[39mcargs, \u001b[39m*\u001b[39m\u001b[39m*\u001b[39mcparams)\n",
      "File \u001b[1;32mc:\\Python39\\lib\\site-packages\\mysql\\connector\\pooling.py:322\u001b[0m, in \u001b[0;36mconnect\u001b[1;34m(*args, **kwargs)\u001b[0m\n\u001b[0;32m    319\u001b[0m         \u001b[39mraise\u001b[39;00m \u001b[39mImportError\u001b[39;00m(ERROR_NO_CEXT)\n\u001b[0;32m    321\u001b[0m \u001b[39mif\u001b[39;00m CMySQLConnection \u001b[39mand\u001b[39;00m \u001b[39mnot\u001b[39;00m use_pure:\n\u001b[1;32m--> 322\u001b[0m     \u001b[39mreturn\u001b[39;00m CMySQLConnection(\u001b[39m*\u001b[39margs, \u001b[39m*\u001b[39m\u001b[39m*\u001b[39mkwargs)\n\u001b[0;32m    323\u001b[0m \u001b[39mreturn\u001b[39;00m MySQLConnection(\u001b[39m*\u001b[39margs, \u001b[39m*\u001b[39m\u001b[39m*\u001b[39mkwargs)\n",
      "File \u001b[1;32mc:\\Python39\\lib\\site-packages\\mysql\\connector\\connection_cext.py:140\u001b[0m, in \u001b[0;36mCMySQLConnection.__init__\u001b[1;34m(self, **kwargs)\u001b[0m\n\u001b[0;32m    138\u001b[0m \u001b[39mif\u001b[39;00m kwargs:\n\u001b[0;32m    139\u001b[0m     \u001b[39mtry\u001b[39;00m:\n\u001b[1;32m--> 140\u001b[0m         \u001b[39mself\u001b[39m\u001b[39m.\u001b[39mconnect(\u001b[39m*\u001b[39m\u001b[39m*\u001b[39mkwargs)\n\u001b[0;32m    141\u001b[0m     \u001b[39mexcept\u001b[39;00m \u001b[39mException\u001b[39;00m:\n\u001b[0;32m    142\u001b[0m         \u001b[39mself\u001b[39m\u001b[39m.\u001b[39mclose()\n",
      "File \u001b[1;32mc:\\Python39\\lib\\site-packages\\mysql\\connector\\abstracts.py:1363\u001b[0m, in \u001b[0;36mMySQLConnectionAbstract.connect\u001b[1;34m(self, **kwargs)\u001b[0m\n\u001b[0;32m   1360\u001b[0m     \u001b[39mself\u001b[39m\u001b[39m.\u001b[39mconfig(\u001b[39m*\u001b[39m\u001b[39m*\u001b[39mkwargs)\n\u001b[0;32m   1362\u001b[0m \u001b[39mself\u001b[39m\u001b[39m.\u001b[39mdisconnect()\n\u001b[1;32m-> 1363\u001b[0m \u001b[39mself\u001b[39;49m\u001b[39m.\u001b[39;49m_open_connection()\n\u001b[0;32m   1365\u001b[0m charset, collation \u001b[39m=\u001b[39m (\n\u001b[0;32m   1366\u001b[0m     kwargs\u001b[39m.\u001b[39mpop(\u001b[39m\"\u001b[39m\u001b[39mcharset\u001b[39m\u001b[39m\"\u001b[39m, \u001b[39mNone\u001b[39;00m),\n\u001b[0;32m   1367\u001b[0m     kwargs\u001b[39m.\u001b[39mpop(\u001b[39m\"\u001b[39m\u001b[39mcollation\u001b[39m\u001b[39m\"\u001b[39m, \u001b[39mNone\u001b[39;00m),\n\u001b[0;32m   1368\u001b[0m )\n\u001b[0;32m   1369\u001b[0m \u001b[39mif\u001b[39;00m charset \u001b[39mor\u001b[39;00m collation:\n",
      "File \u001b[1;32mc:\\Python39\\lib\\site-packages\\mysql\\connector\\connection_cext.py:328\u001b[0m, in \u001b[0;36mCMySQLConnection._open_connection\u001b[1;34m(self)\u001b[0m\n\u001b[0;32m    326\u001b[0m         \u001b[39mself\u001b[39m\u001b[39m.\u001b[39mconverter\u001b[39m.\u001b[39mstr_fallback \u001b[39m=\u001b[39m \u001b[39mself\u001b[39m\u001b[39m.\u001b[39m_converter_str_fallback\n\u001b[0;32m    327\u001b[0m \u001b[39mexcept\u001b[39;00m MySQLInterfaceError \u001b[39mas\u001b[39;00m err:\n\u001b[1;32m--> 328\u001b[0m     \u001b[39mraise\u001b[39;00m get_mysql_exception(\n\u001b[0;32m    329\u001b[0m         msg\u001b[39m=\u001b[39merr\u001b[39m.\u001b[39mmsg, errno\u001b[39m=\u001b[39merr\u001b[39m.\u001b[39merrno, sqlstate\u001b[39m=\u001b[39merr\u001b[39m.\u001b[39msqlstate\n\u001b[0;32m    330\u001b[0m     ) \u001b[39mfrom\u001b[39;00m \u001b[39merr\u001b[39;00m\n\u001b[0;32m    332\u001b[0m \u001b[39mself\u001b[39m\u001b[39m.\u001b[39m_do_handshake()\n",
      "\u001b[1;31mProgrammingError\u001b[0m: (mysql.connector.errors.ProgrammingError) 1045 (28000): Accès refusé pour l'utilisateur: 'ouael'@'@localhost' (mot de passe: OUI)\n(Background on this error at: https://sqlalche.me/e/14/f405)"
     ]
    }
   ],
   "source": [
    "from Medfl.LearningManager.utils import *\n"
   ]
  },
  {
   "cell_type": "code",
   "execution_count": null,
   "metadata": {},
   "outputs": [],
   "source": []
  }
 ],
 "metadata": {
  "kernelspec": {
   "display_name": "Python 3",
   "language": "python",
   "name": "python3"
  },
  "language_info": {
   "codemirror_mode": {
    "name": "ipython",
    "version": 3
   },
   "file_extension": ".py",
   "mimetype": "text/x-python",
   "name": "python",
   "nbconvert_exporter": "python",
   "pygments_lexer": "ipython3",
   "version": "3.9.4"
  },
  "orig_nbformat": 4
 },
 "nbformat": 4,
 "nbformat_minor": 2
}
